Workbook

Sheet MARGASARI_KALISALAK(1)
A1: NO | B1: KEC_ID | C1: KECAMATAN | D1: KEL_ID | E1: KELURAHAN | F1: DPID | G1: NKK | H1: NIK | I1: NAMA | J1: TEMPAT LAHIR | K1: TANGGAL LAHIR | L1: STS KAWIN | M1: KELAMIN | N1: ALAMAT | O1: RT | P1: RW | Q1: DISABILITAS | R1: EKTP | S1: KETERANGAN | T1: SUMBER | U1: TPS_ID | V1: TPS | W1: K1 | X1: K2 | Y1: K3 | Z1: UPDATED_AT | AA1: STATUS | AB1: RANK | AC1: TAHAPAN_ID | AD1: PROV_ASAL | AE1: KAB_ASAL | AF1: KEC_ASAL | AG1: KEL_ASAL
A2: 1 | B2: 3695 | C2: MARGASARI | D2: 47273 | E2: KALISALAK | F2: 1161935 | G2: 3311111605170002 | H2: 3328011005960006 | I2: ARIFIN | J2: TEGAL | K2: 10|05|1996 | L2: S | M2: L | N2: KALISALAK | O2: 1 | P2: 1 | Q2: 0 | R2: s | S2: 0 | T2: dp4 | U2: 1347273001 | V2: 1 | W2: null | X2: null | Y2: null | Z2: 45453 | AA2: aktif | AB2: aktif | AC2: 1 | AD2: null | AE2: null | AF2: null | AG2: null
A3: 2 | B3: 3695 | C3: MARGASARI | D3: 47273 | E3: KALISALAK | F3: 1161936 | G3: 3311111605170002 | H3: 3328015312950006 | I3: WASRIPAH | J3: TEGAL | K3: 13|12|1995 | L3: S | M3: P | N3: KALISALAK | O3: 1 | P3: 1 | Q3: 0 | R3: s | S3: 0 | T3: dp4 | U3: 1347273001 | V3: 1 | W3: null | X3: null | Y3: null | Z3: 45453 | AA3: aktif | AB3: aktif | AC3: 1 | AD3: null | AE3: null | AF3: null | AG3: null
A4: 3 | B4: 3695 | C4: MARGASARI | D4: 47273 | E4: KALISALAK | F4: 1161937 | G4: 3328010201150003 | H4: 3328016203870002 | I4: DEWI PURWANTI | J4: TEGAL | K4: 22|03|1987 | L4: S | M4: P | N4: KALISALAK | O4: 1 | P4: 1 | Q4: 0 | R4: s | S4: 0 | T4: dp4 | U4: 1347273001 | V4: 1 | W4: null | X4: null | Y4: null | Z4: 45453 | AA4: aktif | AB4: aktif | AC4: 1 | AD4: null | AE4: null | AF4: null | AG4: null
A5: 4 | B5: 3695 | C5: MARGASARI | D5: 47273 | E5: KALISALAK | F5: 1161938 | G5: 3328010201150003 | H5: 3328012306830006 | I5: SOFYAN SAHURI | J5: TEGAL | K5: 23|06|1983 | L5: S | M5: L | N5: KALISALAK | O5: 1 | P5: 1 | Q5: 0 | R5: s | S5: 0 | T5: dp4 | U5: 1347273001 | V5: 1 | W5: null | X5: null | Y5: null | Z5: 45453 | AA5: aktif | AB5: aktif | AC5: 1 | AD5: null | AE5: null | AF5: null | AG5: null
A6: 5 | B6: 3695 | C6: MARGASARI | D6: 47273 | E6: KALISALAK | F6: 1161939 | G6: 3328010201240011 | H6: 3328010609990006 | I6: MOCH. ZAEDI AKBAR | J6: MAJALENGKA | K6: 06|09|1999 | L6: B | M6: L | N6: KALISALAK | O6: 1 | P6: 1 | Q6: 0 | R6: s | S6: 0 | T6: dp4 | U6: 1347273001 | V6: 1 | W6: null | X6: null | Y6: null | Z6: 45453 | AA6: aktif | AB6: aktif | AC6: 1 | AD6: null | AE6: null | AF6: null | AG6: null
A7: 6 | B7: 3695 | C7: MARGASARI | D7: 47273 | E7: KALISALAK | F7: 1161940 | G7: 3328010203160010 | H7: 3328016104630005 | I7: MASPUPAH | J7: TEGAL | K7: 21|04|1963 | L7: P | M7: P | N7: KALI SALAK | O7: 1 | P7: 1 | Q7: 0 | R7: s | S7: 0 | T7: dp4 | U7: 1347273001 | V7: 1 | W7: null | X7: null | Y7: null | Z7: 45453 | AA7: aktif | AB7: aktif | AC7: 1 | AD7: null | AE7: null | AF7: null | AG7: null
A8: 7 | B8: 3695 | C8: MARGASARI | D8: 47273 | E8: KALISALAK | F8: 1161941 | G8: 3328010203220015 | H8: 3309065511950002 | I8: SRI WAHYUNI | J8: BOYOLALI | K8: 15|11|1995 | L8: S | M8: P | N8: KALISALAK | O8: 1 | P8: 1 | Q8: 0 | R8: s | S8: 0 | T8: dp4 | U8: 1347273001 | V8: 1 | W8: null | X8: null | Y8: null | Z8: 45453 | AA8: aktif | AB8: aktif | AC8: 1 | AD8: null | AE8: null | AF8: null | AG8: null
A9: 8 | B9: 3695 | C9: MARGASARI | D9: 47273 | E9: KALISALAK | F9: 1161942 | G9: 3328010203220015 | H9: 3328011607970004 | I9: M. AGUNG PRASETYO | J9: TEGAL | K9: 16|06|1997 | L9: S | M9: L | N9: KALISALAK | O9: 1 | P9: 1 | Q9: 0 | R9: s | S9: 0 | T9: dp4 | U9: 1347273001 | V9: 1 | W9: null | X9: null | Y9: null | Z9: 45453 | AA9: aktif | AB9: aktif | AC9: 1 | AD9: null | AE9: null | AF9: null | AG9: null
A10: 9 | B10: 3695 | C10: MARGASARI | D10: 47273 | E10: KALISALAK | F10: 1161944 | G10: 3328010206200003 | H10: 3328010112970003 | I10: MEI DWI PURWANTO | J10: TEGAL | K10: 22|05|1996 | L10: S | M10: L | N10: KALISALAK | O10: 1 | P10: 1 | Q10: 0 | R10: s | S10: 0 | T10: dp4 | U10: 1347273001 | V10: 1 | W10: null | X10: null | Y10: null | Z10: 45453 | AA10: aktif | AB10: aktif | AC10: 1 | AD10: null | AE10: null | AF10: null | AG10: null
A11: 10 | B11: 3695 | C11: MARGASARI | D11: 47273 | E11: KALISALAK | F11: 1161945 | G11: 3328010206200003 | H11: 3328014910950004 | I11: ELI SUSANTI | J11: TEGAL | K11: 01|11|1995 | L11: S | M11: P | N11: KALISALAK | O11: 1 | P11: 1 | Q11: 0 | R11: s | S11: 0 | T11: dp4 | U11: 1347273001 | V11: 1 | W11: null | X11: null | Y11: null | Z11: 45453 | AA11: aktif | AB11: aktif | AC11: 1 | AD11: null | AE11: null | AF11: null | AG11: null
A12: 11 | B12: 3695 | C12: MARGASARI | D12: 47273 | E12: KALISALAK | F12: 1161946 | G12: 3328010211180006 | H12: 3328017112430064 | I12: WATIAH | J12: TEGAL | K12: 31|12|1943 | L12: P | M12: P | N12: DESA KALISALAK | O12: 1 | P12: 1 | Q12: 0 | R12: s | S12: 0 | T12: dp4 | U12: 1347273001 | V12: 1 | W12: null | X12: null | Y12: null | Z12: 45453 | AA12: aktif | AB12: aktif | AC12: 1 | AD12: null | AE12: null | AF12: null | AG12: null
A13: 12 | B13: 3695 | C13: MARGASARI | D13: 47273 | E13: KALISALAK | F13: 1161947 | G13: 3328010212130009 | H13: 3328016303840008 | I13: ALJAZIROH | J13: TEGAL | K13: 23|03|1984 | L13: S | M13: P | N13: KALI SALAK | O13: 1 | P13: 1 | Q13: 0 | R13: s | S13: 0 | T13: dp4 | U13: 1347273001 | V13: 1 | W13: null | X13: null | Y13: null | Z13: 45453 | AA13: aktif | AB13: aktif | AC13: 1 | AD13: null | AE13: null | AF13: null | AG13: null
... A103: 102 | B103: 3695 | C103: MARGASARI | D103: 47273 | E103: KALISALAK | F103: 1162042 | G103: 3328011807110026 | H103: 3328011906930006 | I103: WANTORO | J103: TEGAL | K103: 19|06|1993 | L103: B | M103: L | N103: KALISALAK | O103: 1 | P103: 1 | Q103: 0 | R103: s | S103: 0 | T103: dp4 | U103: 1347273001 | V103: 1 | W103: null | X103: null | Y103: null | Z103: 45453 | AA103: aktif | AB103: aktif | AC103: 1 | AD103: null | AE103: null | AF103: null | AG103: null
A104: 103 | B104: 3695 | C104: MARGASARI | D104: 47273 | E104: KALISALAK | F104: 1162043 | G104: 3328010201240011 | H104: 3328015810000005 | I104: NOFIYA | J104: TEGAL | K104: 18|10|2000 | L104: B | M104: P | N104: KALISALAK | O104: 1 | P104: 1 | Q104: 0 | R104: s | S104: u | T104: coklit | U104: 1347273001 | V104: 1 | W104: null | X104: null | Y104: null | Z104: 45497 | AA104: ubah | AB104: ubah | AC104: 2 | AD104: null | AE104: null | AF104: null | AG104: null
A105: 104 | B105: 3695 | C105: MARGASARI | D105: 47273 | E105: KALISALAK | F105: 1162044 | G105: 3328011811190002 | H105: 3328011212960008 | I105: RIZAL IRWANTO | J105: TEGAL | K105: 12|12|1995 | L105: S | M105: L | N105: KALISALAK | O105: 1 | P105: 1 | Q105: 0 | R105: s | S105: 0 | T105: dp4 | U105: 1347273001 | V105: 1 | W105: null | X105: null | Y105: null | Z105: 45453 | AA105: aktif | AB105: aktif | AC105: 1 | AD105: null | AE105: null | AF105: null | AG105: null
A106: 105 | B106: 3695 | C106: MARGASARI | D106: 47273 | E106: KALISALAK | F106: 1162045 | G106: 3328011811190002 | H106: 3328015701980004 | I106: ELMI VIRGIANI | J106: TEGAL | K106: 17|01|1998 | L106: S | M106: P | N106: KALISALAK | O106: 1 | P106: 1 | Q106: 0 | R106: s | S106: 0 | T106: dp4 | U106: 1347273001 | V106: 1 | W106: null | X106: null | Y106: null | Z106: 45453 | AA106: aktif | AB106: aktif | AC106: 1 | AD106: null | AE106: null | AF106: null | AG106: null
A107: 106 | B107: 3695 | C107: MARGASARI | D107: 47273 | E107: KALISALAK | F107: 1162046 | G107: 3328012009110030 | H107: 3328011410880002 | I107: DEDI IRAWAN | J107: TEGAL | K107: 14|10|1988 | L107: S | M107: L | N107: KALI SALAK | O107: 1 | P107: 1 | Q107: 0 | R107: s | S107: 0 | T107: dp4 | U107: 1347273001 | V107: 1 | W107: null | X107: null | Y107: null | Z107: 45453 | AA107: aktif | AB107: aktif | AC107: 1 | AD107: null | AE107: null | AF107: null | AG107: null
A108: 107 | B108: 3695 | C108: MARGASARI | D108: 47273 | E108: KALISALAK | F108: 1162047 | G108: 3328012009110030 | H108: 3328016006890005 | I108: SITI MASITOH | J108: TEGAL | K108: 20|06|1989 | L108: S | M108: P | N108: KALI SALAK | O108: 1 | P108: 1 | Q108: 0 | R108: s | S108: 0 | T108: dp4 | U108: 1347273001 | V108: 1 | W108: null | X108: null | Y108: null | Z108: 45453 | AA108: aktif | AB108: aktif | AC108: 1 | AD108: null | AE108: null | AF108: null | AG108: null
A109: 108 | B109: 3695 | C109: MARGASARI | D109: 47273 | E109: KALISALAK | F109: 1162048 | G109: 3328012009160007 | H109: 3328017112550055 | I109: KHOLIPAH | J109: TEGAL | K109: 31|12|1955 | L109: P | M109: P | N109: KALISALAK | O109: 1 | P109: 1 | Q109: 0 | R109: s | S109: 0 | T109: dp4 | U109: 1347273001 | V109: 1 | W109: null | X109: null | Y109: null | Z109: 45453 | AA109: aktif | AB109: aktif | AC109: 1 | AD109: null | AE109: null | AF109: null | AG109: null
A110: 109 | B110: 3695 | C110: MARGASARI | D110: 47273 | E110: KALISALAK | F110: 1162051 | G110: 3328012302086097 | H110: 3328012802780004 | I110: WAKHYUDIN | J110: TEGAL | K110: 28|02|1978 | L110: S | M110: L | N110: KALI SALAK | O110: 1 | P110: 1 | Q110: 0 | R110: s | S110: 0 | T110: dp4 | U110: 1347273001 | V110: 1 | W110: null | X110: null | Y110: null | Z110: 45453 | AA110: aktif | AB110: aktif | AC110: 1 | AD110: null | AE110: null | AF110: null | AG110: null
A111: 110 | B111: 3695 | C111: MARGASARI | D111: 47273 | E111: KALISALAK | F111: 1162052 | G111: 3328012302086097 | H111: 3328016708850002 | I111: EPI SUSMAWATI | J111: TEGAL | K111: 27|08|1985 | L111: S | M111: P | N111: KALI SALAK | O111: 1 | P111: 1 | Q111: 0 | R111: s | S111: 0 | T111: dp4 | U111: 1347273001 | V111: 1 | W111: null | X111: null | Y111: null | Z111: 45453 | AA111: aktif | AB111: aktif | AC111: 1 | AD111: null | AE111: null | AF111: null | AG111: null
A112: 111 | B112: 3695 | C112: MARGASARI | D112: 47273 | E112: KALISALAK | F112: 1162053 | G112: 3328012302086097 | H112: 3328016010070004 | I112: ANISA MAULA SAFITRI | J112: TEGAL | K112: 20|10|2007 | L112: B | M112: P | N112: KALI SALAK | O112: 1 | P112: 1 | Q112: 0 | R112: b | S112: 0 | T112: dp4 | U112: 1347273001 | V112: 1 | W112: null | X112: null | Y112: null | Z112: 45453 | AA112: aktif | AB112: aktif | AC112: 1 | AD112: null | AE112: null | AF112: null | AG112: null
A113: 112 | B113: 3695 | C113: MARGASARI | D113: 47273 | E113: KALISALAK | F113: 1162054 | G113: 3328012302086098 | H113: 3328011206010006 | I113: M. DIKI PRASETIO | J113: TEGAL | K113: 12|06|2001 | L113: B | M113: L | N113: KALISALAK | O113: 1 | P113: 1 | Q113: 0 | R113: s | S113: 0 | T113: dp4 | U113: 1347273001 | V113: 1 | W113: null | X113: null | Y113: null | Z113: 45453 | AA113: aktif | AB113: aktif | AC113: 1 | AD113: null | AE113: null | AF113: null | AG113: null
A114: 113 | B114: 3695 | C114: MARGASARI | D114: 47273 | E114: KALISALAK | F114: 1162055 | G114: 3328012302086098 | H114: 3328013112350080 | I114: TAKRIM | J114: TEGAL | K114: 31|12|1935 | L114: P | M114: L | N114: KALISALAK | O114: 1 | P114: 1 | Q114: 0 | R114: s | S114: 0 | T114: dp4 | U114: 1347273001 | V114: 1 | W114: null | X114: null | Y114: null | Z114: 45453 | AA114: aktif | AB114: aktif | AC114: 1 | AD114: null | AE114: null | AF114: null | AG114: null
A115: 114 | B115: 3695 | C115: MARGASARI | D115: 47273 | E115: KALISALAK | F115: 1162056 | G115: 3328012302086098 | H115: 3328015506780007 | I115: SAINAH | J115: TEGAL | K115: 15|06|1978 | L115: S | M115: P | N115: KALISALAK | O115: 1 | P115: 1 | Q115: 0 | R115: s | S115: 0 | T115: dp4 | U115: 1347273001 | V115: 1 | W115: null | X115: null | Y115: null | Z115: 45453 | AA115: aktif | AB115: aktif | AC115: 1 | AD115: null | AE115: null | AF115: null | AG115: null
A116: 115 | B116: 3695 | C116: MARGASARI | D116: 47273 | E116: KALISALAK | F116: 1162057 | G116: 3328012302086098 | H116: 3328012010770003 | I116: SLAMET RIYADI | J116: TEGAL | K116: 20|10|1977 | L116: S | M116: L | N116: KALISALAK | O116: 1 | P116: 1 | Q116: 0 | R116: s | S116: 0 | T116: dp4 | U116: 1347273001 | V116: 1 | W116: null | X116: null | Y116: null | Z116: 45453 | AA116: aktif | AB116: aktif | AC116: 1 | AD116: null | AE116: null | AF116: null | AG116: null
... A140: 139 | B140: 3695 | C140: MARGASARI | D140: 47273 | E140: KALISALAK | F140: 1162081 | G140: 3328012302088980 | H140: 3328015002000012 | I140: FEBRI INTAN LISTIANA | J140: TEGAL | K140: 10|02|2000 | L140: B | M140: P | N140: KALISALAK | O140: 1 | P140: 1 | Q140: 0 | R140: s | S140: 0 | T140: dp4 | U140: 1347273001 | V140: 1 | W140: null | X140: null | Y140: null | Z140: 45453 | AA140: aktif | AB140: aktif | AC140: 1 | AD140: null | AE140: null | AF140: null | AG140: null
A141: 140 | B141: 3695 | C141: MARGASARI | D141: 47273 | E141: KALISALAK | F141: 1162082 | G141: 3328012302088980 | H141: 3328016504070008 | I141: PRISILIA DWI LISTANIA | J141: TEGAL | K141: 25|04|2007 | L141: B | M141: P | N141: KALISALAK | O141: 1 | P141: 1 | Q141: 0 | R141: s | S141: u | T141: kemendagri | U141: 1347273001 | V141: 1 | W141: null | X141: null | Y141: null | Z141: 45541 | AA141: ubah | AB141: ubah | AC141: 4 | AD141: null | AE141: null | AF141: null | AG141: null
A142: 141 | B142: 3695 | C142: MARGASARI | D142: 47273 | E142: KALISALAK | F142: 1162083 | G142: 3328012302088980 | H142: 3328011409760002 | I142: SODLI | J142: TEGAL | K142: 14|09|1976 | L142: S | M142: L | N142: KALISALAK | O142: 1 | P142: 1 | Q142: 0 | R142: s | S142: 0 | T142: dp4 | U142: 1347273001 | V142: 1 | W142: null | X142: null | Y142: null | Z142: 45453 | AA142: aktif | AB142: aktif | AC142: 1 | AD142: null | AE142: null | AF142: null | AG142: null
A143: 142 | B143: 3695 | C143: MARGASARI | D143: 47273 | E143: KALISALAK | F143: 1162084 | G143: 3328012302088982 | H143: 3328013012020006 | I143: M. RIYAN SAPUTRA | J143: TEGAL | K143: 30|12|2002 | L143: B | M143: L | N143: KALISALAK | O143: 1 | P143: 1 | Q143: 0 | R143: s | S143: 0 | T143: dp4 | U143: 1347273001 | V143: 1 | W143: null | X143: null | Y143: null | Z143: 45453 | AA143: aktif | AB143: aktif | AC143: 1 | AD143: null | AE143: null | AF143: null | AG143: null
A144: 143 | B144: 3695 | C144: MARGASARI | D144: 47273 | E144: KALISALAK | F144: 1162085 | G144: 3328012302088982 | H144: 3328017012730011 | I144: KATIRAH | J144: TEGAL | K144: 30|12|1973 | L144: P | M144: P | N144: KALISALAK | O144: 1 | P144: 1 | Q144: 0 | R144: s | S144: 0 | T144: dp4 | U144: 1347273001 | V144: 1 | W144: null | X144: null | Y144: null | Z144: 45453 | AA144: aktif | AB144: aktif | AC144: 1 | AD144: null | AE144: null | AF144: null | AG144: null
A145: 144 | B145: 3695 | C145: MARGASARI | D145: 47273 | E145: KALISALAK | F145: 1162086 | G145: 3328012302088983 | H145: 3328015608020006 | I145: PUTRI SARI | J145: TEGAL | K145: 16|08|2002 | L145: B | M145: P | N145: KALISALAK | O145: 1 | P145: 1 | Q145: 0 | R145: s | S145: 0 | T145: dp4 | U145: 1347273001 | V145: 1 | W145: null | X145: null | Y145: null | Z145: 45453 | AA145: aktif | AB145: aktif | AC145: 1 | AD145: null | AE145: null | AF145: null | AG145: null
A146: 145 | B146: 3695 | C146: MARGASARI | D146: 47273 | E146: KALISALAK | F146: 1162087 | G146: 3328012302088983 | H146: 3328010906800004 | I146: ROPII | J146: TEGAL | K146: 09|06|1980 | L146: S | M146: L | N146: KALISALAK | O146: 1 | P146: 1 | Q146: 0 | R146: s | S146: 0 | T146: dp4 | U146: 1347273001 | V146: 1 | W146: null | X146: null | Y146: null | Z146: 45453 | AA146: aktif | AB146: aktif | AC146: 1 | AD146: null | AE146: null | AF146: null | AG146: null
A147: 146 | B147: 3695 | C147: MARGASARI | D147: 47273 | E147: KALISALAK | F147: 1162088 | G147: 3328012302088983 | H147: 3328015503770006 | I147: SARIPAH | J147: TEGAL | K147: 15|03|1977 | L147: S | M147: P | N147: KALISALAK | O147: 1 | P147: 1 | Q147: 0 | R147: s | S147: 0 | T147: dp4 | U147: 1347273001 | V147: 1 | W147: null | X147: null | Y147: null | Z147: 45453 | AA147: aktif | AB147: aktif | AC147: 1 | AD147: null | AE147: null | AF147: null | AG147: null
A148: 147 | B148: 3695 | C148: MARGASARI | D148: 47273 | E148: KALISALAK | F148: 1162089 | G148: 3328012302088985 | H148: 3328010206610003 | I148: MAHROJI | J148: TEGAL | K148: 02|06|1961 | L148: S | M148: L | N148: KALISALAK | O148: 1 | P148: 1 | Q148: 0 | R148: s | S148: 0 | T148: dp4 | U148: 1347273001 | V148: 1 | W148: null | X148: null | Y148: null | Z148: 45453 | AA148: aktif | AB148: aktif | AC148: 1 | AD148: null | AE148: null | AF148: null | AG148: null
A149: 148 | B149: 3695 | C149: MARGASARI | D149: 47273 | E149: KALISALAK | F149: 1162090 | G149: 3328012302088985 | H149: 3328014804650003 | I149: WATIKHA | J149: TEGAL | K149: 08|04|1965 | L149: S | M149: P | N149: KALISALAK | O149: 1 | P149: 1 | Q149: 0 | R149: s | S149: 0 | T149: dp4 | U149: 1347273001 | V149: 1 | W149: null | X149: null | Y149: null | Z149: 45453 | AA149: aktif | AB149: aktif | AC149: 1 | AD149: null | AE149: null | AF149: null | AG149: null
A150: 149 | B150: 3695 | C150: MARGASARI | D150: 47273 | E150: KALISALAK | F150: 1162091 | G150: 3328012302088987 | H150: 3328010604640002 | I150: TASMUDI | J150: TEGAL | K150: 06|04|1964 | L150: S | M150: L | N150: KALISALAK | O150: 1 | P150: 1 | Q150: 0 | R150: s | S150: 0 | T150: dp4 | U150: 1347273001 | V150: 1 | W150: null | X150: null | Y150: null | Z150: 45453 | AA150: aktif | AB150: aktif | AC150: 1 | AD150: null | AE150: null | AF150: null | AG150: null
A151: 150 | B151: 3695 | C151: MARGASARI | D151: 47273 | E151: KALISALAK | F151: 1162092 | G151: 3328012302088987 | H151: 3328016306690001 | I151: NIKEN KUSUMARINI | J151: TEGAL | K151: 23|06|1969 | L151: S | M151: P | N151: KALISALAK | O151: 1 | P151: 1 | Q151: 0 | R151: s | S151: 0 | T151: dp4 | U151: 1347273001 | V151: 1 | W151: null | X151: null | Y151: null | Z151: 45453 | AA151: aktif | AB151: aktif | AC151: 1 | AD151: null | AE151: null | AF151: null | AG151: null
A152: 151 | B152: 3695 | C152: MARGASARI | D152: 47273 | E152: KALISALAK | F152: 1162093 | G152: 3328012302088988 | H152: 3328011312400003 | I152: SAYAD | J152: TEGAL | K152: 13|12|1940 | L152: S | M152: L | N152: KALISALAK | O152: 1 | P152: 1 | Q152: 0 | R152: s | S152: 0 | T152: dp4 | U152: 1347273001 | V152: 1 | W152: null | X152: null | Y152: null | Z152: 45453 | AA152: aktif | AB152: aktif | AC152: 1 | AD152: null | AE152: null | AF152: null | AG152: null
...

Sheet DATA DPK
A1: NO | B1: NKK | C1: NIK | D1: NAMA | E1: TEMPAT LAHIR | F1: KELAMIN | G1: ALAMAT | H1: TPS | I1: ALAMAT TPS
A2: 1 | B2: 2 | C2: 3 | D2: 4 | E2: 5 | F2: 6 | G2: 7 | H2: 8 | I2: 9
A3: 1 | B3: 3311111605170002 | C3: 3328011005960006 | D3: ARIFIN | E3: Tegal, | F3: Laki - laki | G3: Kalisalak Rt. Rw. | H3: 1 | I3: =IF(H3=1,"Depan Rumah Bp.Tamri",IF(H3=2,"Lapangan Volly",IF(H3=3,"Halaman MI NU 01 Kalisalak",IF(H3=4,"Halaman Rumah Ibu Rikhanah",IF(H3=5,"Halaman Rumah Alm. Bp. Ust. Sukhari",IF(H3=6,"Halaman Musholla Baitul Muhajirin",IF(H3=7,"Depan Musholla Al Athar",IF(H3=8,"MI Nurul Huda Kalisalak",IF(H3=9,"Halaman Musholla Baitul Muttaqin",IF(H3=10,"Halaman Rumah Bp. Sonhaji",IF(H3=11,"Halaman Bp.Priyadi Ibu Munawaroh",IF(H3=12,"Halaman Rumah Ibu Nurhayati Bp.Usd. Piing (Alm)",IF(H3=13,"Halaman SDN Kalisalak 03",IF(H3=14,"Halaman Musholla Baitul Marwah",0)))))))))))))) -> Depan Rumah Bp.Tamri
A4: 2 | B4: 3311111605170002 | C4: 3328015312950006 | D4: WASRIPAH | E4: Tegal, | F4: Perempuan | G4: Kalisalak Rt. Rw. | H4: 2 | I4: =IF(H4=1,"Depan Rumah Bp.Tamri",IF(H4=2,"Lapangan Volly",IF(H4=3,"Halaman MI NU 01 Kalisalak",IF(H4=4,"Halaman Rumah Ibu Rikhanah",IF(H4=5,"Halaman Rumah Alm. Bp. Ust. Sukhari",IF(H4=6,"Halaman Musholla Baitul Muhajirin",IF(H4=7,"Depan Musholla Al Athar",IF(H4=8,"MI Nurul Huda Kalisalak",IF(H4=9,"Halaman Musholla Baitul Muttaqin",IF(H4=10,"Halaman Rumah Bp. Sonhaji",IF(H4=11,"Halaman Bp.Priyadi Ibu Munawaroh",IF(H4=12,"Halaman Rumah Ibu Nurhayati Bp.Usd. Piing (Alm)",IF(H4=13,"Halaman SDN Kalisalak 03",IF(H4=14,"Halaman Musholla Baitul Marwah",0)))))))))))))) -> Lapangan Volly
A5: 3 | B5: 3328010201150003 | C5: 3328016203870002 | D5: DEWI PURWANTI | E5: Tegal, | F5: Laki - laki | G5: Kalisalak Rt. Rw. | H5: 3 | I5: =IF(H5=1,"Depan Rumah Bp.Tamri",IF(H5=2,"Lapangan Volly",IF(H5=3,"Halaman MI NU 01 Kalisalak",IF(H5=4,"Halaman Rumah Ibu Rikhanah",IF(H5=5,"Halaman Rumah Alm. Bp. Ust. Sukhari",IF(H5=6,"Halaman Musholla Baitul Muhajirin",IF(H5=7,"Depan Musholla Al Athar",IF(H5=8,"MI Nurul Huda Kalisalak",IF(H5=9,"Halaman Musholla Baitul Muttaqin",IF(H5=10,"Halaman Rumah Bp. Sonhaji",IF(H5=11,"Halaman Bp.Priyadi Ibu Munawaroh",IF(H5=12,"Halaman Rumah Ibu Nurhayati Bp.Usd. Piing (Alm)",IF(H5=13,"Halaman SDN Kalisalak 03",IF(H5=14,"Halaman Musholla Baitul Marwah",0)))))))))))))) -> Halaman MI NU 01 Kalisalak
A6: 4 | B6: 3328010201150003 | C6: 3328012306830006 | D6: SOFYAN SAHURI | E6: Tegal, | F6: Perempuan | G6: Kalisalak Rt. Rw. | H6: 4 | I6: =IF(H6=1,"Depan Rumah Bp.Tamri",IF(H6=2,"Lapangan Volly",IF(H6=3,"Halaman MI NU 01 Kalisalak",IF(H6=4,"Halaman Rumah Ibu Rikhanah",IF(H6=5,"Halaman Rumah Alm. Bp. Ust. Sukhari",IF(H6=6,"Halaman Musholla Baitul Muhajirin",IF(H6=7,"Depan Musholla Al Athar",IF(H6=8,"MI Nurul Huda Kalisalak",IF(H6=9,"Halaman Musholla Baitul Muttaqin",IF(H6=10,"Halaman Rumah Bp. Sonhaji",IF(H6=11,"Halaman Bp.Priyadi Ibu Munawaroh",IF(H6=12,"Halaman Rumah Ibu Nurhayati Bp.Usd. Piing (Alm)",IF(H6=13,"Halaman SDN Kalisalak 03",IF(H6=14,"Halaman Musholla Baitul Marwah",0)))))))))))))) -> Halaman Rumah Ibu Rikhanah
A7: 5 | E7: Tegal, | F7: Laki - laki | G7: Kalisalak Rt. Rw. | H7: 5 | I7: =IF(H7=1,"Depan Rumah Bp.Tamri",IF(H7=2,"Lapangan Volly",IF(H7=3,"Halaman MI NU 01 Kalisalak",IF(H7=4,"Halaman Rumah Ibu Rikhanah",IF(H7=5,"Halaman Rumah Alm. Bp. Ust. Sukhari",IF(H7=6,"Halaman Musholla Baitul Muhajirin",IF(H7=7,"Depan Musholla Al Athar",IF(H7=8,"MI Nurul Huda Kalisalak",IF(H7=9,"Halaman Musholla Baitul Muttaqin",IF(H7=10,"Halaman Rumah Bp. Sonhaji",IF(H7=11,"Halaman Bp.Priyadi Ibu Munawaroh",IF(H7=12,"Halaman Rumah Ibu Nurhayati Bp.Usd. Piing (Alm)",IF(H7=13,"Halaman SDN Kalisalak 03",IF(H7=14,"Halaman Musholla Baitul Marwah",0)))))))))))))) -> Halaman Rumah Alm. Bp. Ust. Sukhari
A8: 6 | E8: Tegal, | F8: Perempuan | G8: Kalisalak Rt. Rw. | H8: 6 | I8: =IF(H8=1,"Depan Rumah Bp.Tamri",IF(H8=2,"Lapangan Volly",IF(H8=3,"Halaman MI NU 01 Kalisalak",IF(H8=4,"Halaman Rumah Ibu Rikhanah",IF(H8=5,"Halaman Rumah Alm. Bp. Ust. Sukhari",IF(H8=6,"Halaman Musholla Baitul Muhajirin",IF(H8=7,"Depan Musholla Al Athar",IF(H8=8,"MI Nurul Huda Kalisalak",IF(H8=9,"Halaman Musholla Baitul Muttaqin",IF(H8=10,"Halaman Rumah Bp. Sonhaji",IF(H8=11,"Halaman Bp.Priyadi Ibu Munawaroh",IF(H8=12,"Halaman Rumah Ibu Nurhayati Bp.Usd. Piing (Alm)",IF(H8=13,"Halaman SDN Kalisalak 03",IF(H8=14,"Halaman Musholla Baitul Marwah",0)))))))))))))) -> Halaman Musholla Baitul Muhajirin
A9: 7 | E9: Tegal, | F9: Laki - laki | G9: Kalisalak Rt. Rw. | H9: 7 | I9: =IF(H9=1,"Depan Rumah Bp.Tamri",IF(H9=2,"Lapangan Volly",IF(H9=3,"Halaman MI NU 01 Kalisalak",IF(H9=4,"Halaman Rumah Ibu Rikhanah",IF(H9=5,"Halaman Rumah Alm. Bp. Ust. Sukhari",IF(H9=6,"Halaman Musholla Baitul Muhajirin",IF(H9=7,"Depan Musholla Al Athar",IF(H9=8,"MI Nurul Huda Kalisalak",IF(H9=9,"Halaman Musholla Baitul Muttaqin",IF(H9=10,"Halaman Rumah Bp. Sonhaji",IF(H9=11,"Halaman Bp.Priyadi Ibu Munawaroh",IF(H9=12,"Halaman Rumah Ibu Nurhayati Bp.Usd. Piing (Alm)",IF(H9=13,"Halaman SDN Kalisalak 03",IF(H9=14,"Halaman Musholla Baitul Marwah",0)))))))))))))) -> Depan Musholla Al Athar
A10: 8 | E10: Tegal, | F10: Perempuan | G10: Kalisalak Rt. Rw. | H10: 8 | I10: =IF(H10=1,"Depan Rumah Bp.Tamri",IF(H10=2,"Lapangan Volly",IF(H10=3,"Halaman MI NU 01 Kalisalak",IF(H10=4,"Halaman Rumah Ibu Rikhanah",IF(H10=5,"Halaman Rumah Alm. Bp. Ust. Sukhari",IF(H10=6,"Halaman Musholla Baitul Muhajirin",IF(H10=7,"Depan Musholla Al Athar",IF(H10=8,"MI Nurul Huda Kalisalak",IF(H10=9,"Halaman Musholla Baitul Muttaqin",IF(H10=10,"Halaman Rumah Bp. Sonhaji",IF(H10=11,"Halaman Bp.Priyadi Ibu Munawaroh",IF(H10=12,"Halaman Rumah Ibu Nurhayati Bp.Usd. Piing (Alm)",IF(H10=13,"Halaman SDN Kalisalak 03",IF(H10=14,"Halaman Musholla Baitul Marwah",0)))))))))))))) -> MI Nurul Huda Kalisalak
A11: 9 | E11: Tegal, | F11: Laki - laki | G11: Kalisalak Rt. Rw. | H11: 9 | I11: =IF(H11=1,"Depan Rumah Bp.Tamri",IF(H11=2,"Lapangan Volly",IF(H11=3,"Halaman MI NU 01 Kalisalak",IF(H11=4,"Halaman Rumah Ibu Rikhanah",IF(H11=5,"Halaman Rumah Alm. Bp. Ust. Sukhari",IF(H11=6,"Halaman Musholla Baitul Muhajirin",IF(H11=7,"Depan Musholla Al Athar",IF(H11=8,"MI Nurul Huda Kalisalak",IF(H11=9,"Halaman Musholla Baitul Muttaqin",IF(H11=10,"Halaman Rumah Bp. Sonhaji",IF(H11=11,"Halaman Bp.Priyadi Ibu Munawaroh",IF(H11=12,"Halaman Rumah Ibu Nurhayati Bp.Usd. Piing (Alm)",IF(H11=13,"Halaman SDN Kalisalak 03",IF(H11=14,"Halaman Musholla Baitul Marwah",0)))))))))))))) -> Halaman Musholla Baitul Muttaqin
A12: 10 | E12: Tegal, | F12: Perempuan | G12: Kalisalak Rt. Rw. | H12: 10 | I12: =IF(H12=1,"Depan Rumah Bp.Tamri",IF(H12=2,"Lapangan Volly",IF(H12=3,"Halaman MI NU 01 Kalisalak",IF(H12=4,"Halaman Rumah Ibu Rikhanah",IF(H12=5,"Halaman Rumah Alm. Bp. Ust. Sukhari",IF(H12=6,"Halaman Musholla Baitul Muhajirin",IF(H12=7,"Depan Musholla Al Athar",IF(H12=8,"MI Nurul Huda Kalisalak",IF(H12=9,"Halaman Musholla Baitul Muttaqin",IF(H12=10,"Halaman Rumah Bp. Sonhaji",IF(H12=11,"Halaman Bp.Priyadi Ibu Munawaroh",IF(H12=12,"Halaman Rumah Ibu Nurhayati Bp.Usd. Piing (Alm)",IF(H12=13,"Halaman SDN Kalisalak 03",IF(H12=14,"Halaman Musholla Baitul Marwah",0)))))))))))))) -> Halaman Rumah Bp. Sonhaji
A13: 11 | E13: Tegal, | F13: Laki - laki | G13: Kalisalak Rt. Rw. | H13: 11 | I13: =IF(H13=1,"Depan Rumah Bp.Tamri",IF(H13=2,"Lapangan Volly",IF(H13=3,"Halaman MI NU 01 Kalisalak",IF(H13=4,"Halaman Rumah Ibu Rikhanah",IF(H13=5,"Halaman Rumah Alm. Bp. Ust. Sukhari",IF(H13=6,"Halaman Musholla Baitul Muhajirin",IF(H13=7,"Depan Musholla Al Athar",IF(H13=8,"MI Nurul Huda Kalisalak",IF(H13=9,"Halaman Musholla Baitul Muttaqin",IF(H13=10,"Halaman Rumah Bp. Sonhaji",IF(H13=11,"Halaman Bp.Priyadi Ibu Munawaroh",IF(H13=12,"Halaman Rumah Ibu Nurhayati Bp.Usd. Piing (Alm)",IF(H13=13,"Halaman SDN Kalisalak 03",IF(H13=14,"Halaman Musholla Baitul Marwah",0)))))))))))))) -> Halaman Bp.Priyadi Ibu Munawaroh
A14: 12 | E14: Tegal, | F14: Perempuan | G14: Kalisalak Rt. Rw. | H14: 12 | I14: =IF(H14=1,"Depan Rumah Bp.Tamri",IF(H14=2,"Lapangan Volly",IF(H14=3,"Halaman MI NU 01 Kalisalak",IF(H14=4,"Halaman Rumah Ibu Rikhanah",IF(H14=5,"Halaman Rumah Alm. Bp. Ust. Sukhari",IF(H14=6,"Halaman Musholla Baitul Muhajirin",IF(H14=7,"Depan Musholla Al Athar",IF(H14=8,"MI Nurul Huda Kalisalak",IF(H14=9,"Halaman Musholla Baitul Muttaqin",IF(H14=10,"Halaman Rumah Bp. Sonhaji",IF(H14=11,"Halaman Bp.Priyadi Ibu Munawaroh",IF(H14=12,"Halaman Rumah Ibu Nurhayati Bp.Usd. Piing (Alm)",IF(H14=13,"Halaman SDN Kalisalak 03",IF(H14=14,"Halaman Musholla Baitul Marwah",0)))))))))))))) -> Halaman Rumah Ibu Nurhayati Bp.Usd. Piing (Alm)
A15: 13 | E15: Tegal, | F15: Laki - laki | G15: Kalisalak Rt. Rw. | H15: 13 | I15: =IF(H15=1,"Depan Rumah Bp.Tamri",IF(H15=2,"Lapangan Volly",IF(H15=3,"Halaman MI NU 01 Kalisalak",IF(H15=4,"Halaman Rumah Ibu Rikhanah",IF(H15=5,"Halaman Rumah Alm. Bp. Ust. Sukhari",IF(H15=6,"Halaman Musholla Baitul Muhajirin",IF(H15=7,"Depan Musholla Al Athar",IF(H15=8,"MI Nurul Huda Kalisalak",IF(H15=9,"Halaman Musholla Baitul Muttaqin",IF(H15=10,"Halaman Rumah Bp. Sonhaji",IF(H15=11,"Halaman Bp.Priyadi Ibu Munawaroh",IF(H15=12,"Halaman Rumah Ibu Nurhayati Bp.Usd. Piing (Alm)",IF(H15=13,"Halaman SDN Kalisalak 03",IF(H15=14,"Halaman Musholla Baitul Marwah",0)))))))))))))) -> Halaman SDN Kalisalak 03
A16: 14 | E16: Tegal, | F16: Perempuan | G16: Kalisalak Rt. Rw. | H16: 14 | I16: =IF(H16=1,"Depan Rumah Bp.Tamri",IF(H16=2,"Lapangan Volly",IF(H16=3,"Halaman MI NU 01 Kalisalak",IF(H16=4,"Halaman Rumah Ibu Rikhanah",IF(H16=5,"Halaman Rumah Alm. Bp. Ust. Sukhari",IF(H16=6,"Halaman Musholla Baitul Muhajirin",IF(H16=7,"Depan Musholla Al Athar",IF(H16=8,"MI Nurul Huda Kalisalak",IF(H16=9,"Halaman Musholla Baitul Muttaqin",IF(H16=10,"Halaman Rumah Bp. Sonhaji",IF(H16=11,"Halaman Bp.Priyadi Ibu Munawaroh",IF(H16=12,"Halaman Rumah Ibu Nurhayati Bp.Usd. Piing (Alm)",IF(H16=13,"Halaman SDN Kalisalak 03",IF(H16=14,"Halaman Musholla Baitul Marwah",0)))))))))))))) -> Halaman Musholla Baitul Marwah
A17: 15 | E17: Tegal, | F17: Laki - laki | G17: Kalisalak Rt. Rw. | H17: 1 | I17: =IF(H17=1,"Depan Rumah Bp.Tamri",IF(H17=2,"Lapangan Volly",IF(H17=3,"Halaman MI NU 01 Kalisalak",IF(H17=4,"Halaman Rumah Ibu Rikhanah",IF(H17=5,"Halaman Rumah Alm. Bp. Ust. Sukhari",IF(H17=6,"Halaman Musholla Baitul Muhajirin",IF(H17=7,"Depan Musholla Al Athar",IF(H17=8,"MI Nurul Huda Kalisalak",IF(H17=9,"Halaman Musholla Baitul Muttaqin",IF(H17=10,"Halaman Rumah Bp. Sonhaji",IF(H17=11,"Halaman Bp.Priyadi Ibu Munawaroh",IF(H17=12,"Halaman Rumah Ibu Nurhayati Bp.Usd. Piing (Alm)",IF(H17=13,"Halaman SDN Kalisalak 03",IF(H17=14,"Halaman Musholla Baitul Marwah",0)))))))))))))) -> Depan Rumah Bp.Tamri
A18: 16 | E18: Tegal, | F18: Perempuan | G18: Kalisalak Rt. Rw. | H18: 2 | I18: =IF(H18=1,"Depan Rumah Bp.Tamri",IF(H18=2,"Lapangan Volly",IF(H18=3,"Halaman MI NU 01 Kalisalak",IF(H18=4,"Halaman Rumah Ibu Rikhanah",IF(H18=5,"Halaman Rumah Alm. Bp. Ust. Sukhari",IF(H18=6,"Halaman Musholla Baitul Muhajirin",IF(H18=7,"Depan Musholla Al Athar",IF(H18=8,"MI Nurul Huda Kalisalak",IF(H18=9,"Halaman Musholla Baitul Muttaqin",IF(H18=10,"Halaman Rumah Bp. Sonhaji",IF(H18=11,"Halaman Bp.Priyadi Ibu Munawaroh",IF(H18=12,"Halaman Rumah Ibu Nurhayati Bp.Usd. Piing (Alm)",IF(H18=13,"Halaman SDN Kalisalak 03",IF(H18=14,"Halaman Musholla Baitul Marwah",0)))))))))))))) -> Lapangan Volly
... A73: 71 | E73: Tegal, | F73: Perempuan | G73: Kalisalak Rt. Rw. | H73: 14 | I73: =IF(H73=1,"Depan Rumah Bp.Tamri",IF(H73=2,"Lapangan Volly",IF(H73=3,"Halaman MI NU 01 Kalisalak",IF(H73=4,"Halaman Rumah Ibu Rikhanah",IF(H73=5,"Halaman Rumah Alm. Bp. Ust. Sukhari",IF(H73=6,"Halaman Musholla Baitul Muhajirin",IF(H73=7,"Depan Musholla Al Athar",IF(H73=8,"MI Nurul Huda Kalisalak",IF(H73=9,"Halaman Musholla Baitul Muttaqin",IF(H73=10,"Halaman Rumah Bp. Sonhaji",IF(H73=11,"Halaman Bp.Priyadi Ibu Munawaroh",IF(H73=12,"Halaman Rumah Ibu Nurhayati Bp.Usd. Piing (Alm)",IF(H73=13,"Halaman SDN Kalisalak 03",IF(H73=14,"Halaman Musholla Baitul Marwah",0)))))))))))))) -> Halaman Musholla Baitul Marwah

Sheet PRINT
I1: 34
Q3: UNTUK PPS
B8: PANITIA PEMUNGUTAN SUARA | K8: PANITIA PEMUNGUTAN SUARA
B9: DESA KALISALAK | K9: DESA KALISALAK
B11: SURAT KETERANGAN DPK | K11: SURAT KETERANGAN DPK
B13: Nama | E13: : | F13: =VLOOKUP($I$1,'DATA DPK'!A3:I298,4,1) -> 0 | K13: Nama | N13: : | O13: =F13 -> 0
B14: NIK | E14: : | F14: =VLOOKUP($I$1,'DATA DPK'!A3:I298,3,1) -> 0 | K14: NIK | N14: : | O14: =F14 -> 0
B15: Jenis Kelamin | E15: : | F15: =VLOOKUP($I$1,'DATA DPK'!A3:I298,6,1) -> Perempuan | K15: Jenis Kelamin | N15: : | O15: =F15 -> Perempuan
B16: Alamat E KTP | E16: : | F16: =VLOOKUP($I$1,'DATA DPK'!A3:I298,7,1) -> Kalisalak Rt. Rw. | K16: Alamat E KTP | N16: : | O16: =F16 -> Kalisalak Rt. Rw.
B17: TPS | E17: : | F17: =VLOOKUP($I$1,'DATA DPK'!A3:I298,8,1) -> 6 | K17: TPS | N17: : | O17: =F17 -> 6
B18: Alamat TPS | E18: : | F18: =VLOOKUP($I$1,'DATA DPK'!A3:I298,9,1) -> Halaman Musholla Baitul Muhajirin | K18: Alamat TPS | N18: : | O18: =F18 -> Halaman Musholla Baitul Muhajirin
B19: Waktu Pemungutan Suara | E19: : | F19: Pukul 12.00 sd 13.00 WIB | K19: Waktu Pemungutan Suara | N19: : | O19: Pukul 12.00 sd 13.00 WIB
B20: Catatan : | K20: Catatan :
B21: 1. Surat ini adalh sebagai bukti Pemilih DPK ( Daftar Pemilih Khusus ) | K21: 1. Surat ini adalh sebagai bukti Pemilih DPK ( Daftar Pemilih Khusus )
B22: 2. Dilayani sebagai pemilih DPK dengan menunjukan e-KTP Aslinya | K22: 2. Dilayani sebagai pemilih DPK dengan menunjukan e-KTP Aslinya
B23: 3. Dilayani pukul 12.00 sd 13.00 | K23: 3. Dilayani pukul 12.00 sd 13.00
B24: 4. Diberikan 2 jenis Surat Suara | K24: 4. Diberikan 2 jenis Surat Suara
F26: KETUA PPS | O26: KETUA PPS
F30: M. DANUWIYOTO | O30: M. DANUWIYOTO
